import os
from datetime import datetime, timedelta

from dotenv import load_dotenv
from fastapi import Depends, HTTPException, status
from fastapi.security import OAuth2PasswordBearer
from jose import JWTError, jwt
from passlib.context import CryptContext
from sqlalchemy.orm import Session

from app.database import SessionLocal
from app.models import User

load_dotenv()

# Environment secrets
SECRET_KEY = os.getenv("SECRET_KEY")
ALGORITHM = os.getenv("ALGORITHM", "HS256")
ACCESS_TOKEN_EXPIRE_MINUTES = int(os.getenv("ACCESS_TOKEN_EXPIRE_MINUTES", 30))

# Setup password hashing context
pwd_context = CryptContext(schemes=["bcrypt"], deprecated="auto")


def get_password_hash(password):
    return pwd_context.hash(password)


def verify_password(plain_password, hashed_password):
    return pwd_context.verify(plain_password, hashed_password)


def create_access_token(data: dict):
    to_encode = data.copy()
    expire = datetime.utcnow() + timedelta(minutes=ACCESS_TOKEN_EXPIRE_MINUTES)
    to_encode.update({"exp": expire})
    encoded_jwt = jwt.encode(to_encode, SECRET_KEY, algorithm=ALGORITHM)
    return encoded_jwt


oauth2_scheme = OAuth2PasswordBearer(tokenUrl="/login")


def get_db():
    db = SessionLocal()
    try:
        yield db
    finally:
        db.close()


def get_current_user(
    token: str = Depends(oauth2_scheme), db: Session = Depends(get_db)
):
    credentials_exception = HTTPException(
        status_code=status.HTTP_401_UNAUTHORIZED,
        detail="Could not validate credentials",
        headers={"WWW-Authenticate": "Bearer"},
    )
    try:
        payload = jwt.decode(
            token, os.getenv("SECRET_KEY"), algorithms=[os.getenv("ALGORITHM")]
        )
        email: str = payload.get("sub")
        if email is None:
            raise credentials_exception
    except JWTError:
        raise credentials_exception
    user = db.query(User).filter(User.email == email).first()
    if user is None:
        raise credentials_exception
    return user
